Workbook

Sheet Inputs
A1: Cap table - HTGC V1.0 Feb 2010
A2: Hercules Technology Growth Capital
A3: Inputs For Capitalization Table
G4: (User Inputs Blue Text & Numbers)
H6: Company Name: | I6: Company Name
H7: Cap Table Date: | I7: 39813
D8: Capitalization Of Company Since Inception
D9: Name of Round Closed | E9: Date Round Closed | F9: Post-Money | G9: Preference Multiple | H9: Cap | I9: Seniority Rank | J9: Conv. Ratio | K9: Price Per Share | L9: Total Raised | M9: Shares Issued | N9: Warrants Issued | O9: Strike Price
D10: Series A | E10: 39113 | F10: 0 | G10: 1 | H10: 2 | I10: 10 | J10: 1 | K10: 1 | L10: 5000000 | M10: =IFERROR(L10/K10,"") -> 5000000 | N10: 10000 | O10: 1
D11: Series B | E11: =E10+365 -> 39478 | F11: 0 | G11: 1 | H11: 2 | I11: 10 | J11: 1 | K11: 2 | L11: 10000000 | M11: =IFERROR(L11/K11,"") -> 5000000 | N11: 10000 | O11: 1
D12: Series C | E12: =E11+365 -> 39843 | F12: 0 | G12: 1 | H12: 2 | I12: 2 | J12: 1 | K12: 2.5 | L12: 15000000 | M12: =IFERROR(L12/K12,"") -> 6000000 | N12: 10000 | O12: 1
D13: Series D | E13: =E12 -> 39843 | F13: 0 | G13: 1 | H13: 2 | I13: 1 | J13: 1 | K13: 2 | L13: 20000000 | M13: =IFERROR(L13/K13,"") -> 10000000 | N13: 10000 | O13: 1
D14: - | E14: =E13 -> 39843 | F14: 0 | G14: 1 | H14: 2 | I14: 10 | J14: 1 | K14: 0 | L14: 0 | M14: =IFERROR(L14/K14,"") | N14: 0 | O14: 0
D15: - | E15: =E14 -> 39843 | F15: 0 | G15: 1 | H15: 2 | I15: 10 | J15: 1 | K15: 0 | L15: 0 | M15: =IFERROR(L15/K15,"") | N15: 0 | O15: 0
D16: - | E16: =E15 -> 39843 | F16: 0 | G16: 1 | H16: 2 | I16: 10 | J16: 1 | K16: 0 | L16: 0 | M16: =IFERROR(L16/K16,"") | N16: 0 | O16: 0
D17: - | E17: =E16 -> 39843 | F17: 0 | G17: 1 | H17: 2 | I17: 10 | J17: 1 | K17: 0 | L17: 0 | M17: =IFERROR(L17/K17,"") | N17: 0 | O17: 0
D18: - | E18: =E17 -> 39843 | F18: 0 | G18: 1 | H18: 2 | I18: 10 | J18: 1 | K18: 0 | L18: 0 | M18: =IFERROR(L18/K18,"") | N18: 0 | O18: 0
D19: - | E19: =E18 -> 39843 | F19: 0 | G19: 1 | H19: 2 | I19: 10 | J19: 1 | K19: 0 | L19: 0 | M19: =IFERROR(L19/K19,"") | N19: 0 | O19: 0
D20: Warrants | L20: =N10*O10+N11*O11+N12*O12+N13*O13+N14*O14+N15*O15+N16*O16+N17*O17+N18*O18+N19*O19 -> 40000 | M20: =N21 -> 40000 | O20: =N20*P20 -> 0
D21: Subtotal Of All Preferred | L21: =SUM(L10:L20) -> 50040000 | M21: =SUM(M10:M20) -> 26040000 | N21: =SUM(N10:N20) -> 40000
D22: Common Shares Issued | K22: 1e-08 | L22: =M22*K22 -> 0.052 | M22: 5200000
D23: Options (Vested + Authorized) | K23: 1e-07 | L23: =0 -> 0 | M23: 0
D24: Subtotal Of All Common + Options | L24: =SUM(L22:L23) -> 0.052 | M24: =SUM(M22:M23) -> 5200000
D26: TOTALS | L26: =L24+L21 -> 50040000 | M26: =M24+M21 -> 31240000 | N26: =N21+N24 -> 40000
D29: Current Investors - # of Shares Per Round
D30: Investor/Series | E30: Coverage Partner | F30: {=IF(TRANSPOSE(D10:D19)="","",TRANSPOSE(D10:D19))} -> Series A | G30: Series B | H30: Series C | I30: Series D | J30: - | K30: - | L30: - | M30: - | N30: - | O30: - | P30: Common | Q30: Options | R30: TOTAL
D31: HTGC | F31: 1000000 | G31: 1000000 | H31: 0 | I31: 0 | J31: 0 | K31: 0 | L31: 0 | M31: 0 | N31: 0 | O31: 0 | P31: 0 | Q31: 0 | R31: =SUM(F31:Q31) -> 2000000
D32: Inv B | F32: 1000000 | G32: 1000000 | H32: 0 | I32: 0 | J32: 0 | K32: 0 | L32: 0 | M32: 0 | N32: 0 | O32: 0 | P32: 0 | Q32: 0 | R32: =SUM(F32:Q32) -> 2000000
D33: Inv C | F33: 1000000 | G33: 1000000 | H33: 1000000 | I33: 0 | J33: 0 | K33: 0 | L33: 0 | M33: 0 | N33: 0 | O33: 0 | P33: 0 | Q33: 0 | R33: =SUM(F33:Q33) -> 3000000
D34: Inv D | F34: 1000000 | G34: 1000000 | H34: 1000000 | I34: 0 | J34: 0 | K34: 0 | L34: 0 | M34: 0 | N34: 0 | O34: 0 | P34: 0 | Q34: 0 | R34: =SUM(F34:Q34) -> 3000000
D35: Inv E | F35: 1000000 | G35: 1000000 | H35: 1000000 | I35: 0 | J35: 0 | K35: 0 | L35: 0 | M35: 0 | N35: 0 | O35: 0 | P35: 0 | Q35: 0 | R35: =SUM(F35:Q35) -> 3000000
D36: Inv F | F36: 0 | G36: 0 | H36: 1000000 | I36: =10000000/3 -> 3333333.3 | J36: 0 | K36: 0 | L36: 0 | M36: 0 | N36: 0 | O36: 0 | P36: 0 | Q36: 0 | R36: =SUM(F36:Q36) -> 4333333.3
D37: Inv G | F37: 0 | G37: 0 | H37: 1000000 | I37: =10000000/3 -> 3333333.3 | J37: 0 | K37: 0 | L37: 0 | M37: 0 | N37: 0 | O37: 0 | P37: 0 | Q37: 0 | R37: =SUM(F37:Q37) -> 4333333.3
D38: Inv H | F38: 0 | G38: 0 | H38: 1000000 | I38: =10000000/3 -> 3333333.3 | J38: 0 | K38: 0 | L38: 0 | M38: 0 | N38: 0 | O38: 0 | P38: 0 | Q38: 0 | R38: =SUM(F38:Q38) -> 4333333.3
D39: Other Investors | F39: 0 | G39: 0 | H39: 0 | I39: 0 | J39: 0 | K39: 0 | L39: 0 | M39: 0 | N39: 0 | O39: 0 | P39: 0 | Q39: 0 | R39: =SUM(F39:Q39) -> 0
D40: Management | P40: 5200000 | Q40: =M23 -> 0 | R40: =SUM(F40:Q40) -> 5200000
D41: Warrants | F41: {=TRANSPOSE(N10:N20)} -> 10000 | G41: 10000 | H41: 10000 | I41: 10000 | J41: 0 | K41: 0 | L41: 0 | M41: 0 | N41: 0 | O41: 0 | R41: =SUM(F41:O41) -> 40000
D42: TOTALS | F42: =IF(SUM(F31:F40)=0,"",SUM(F31:F40)) -> 5000000 | G42: =IF(SUM(G31:G40)=0,"",SUM(G31:G40)) -> 5000000 | H42: =IF(SUM(H31:H40)=0,"",SUM(H31:H40)) -> 6000000 | I42: =IF(SUM(I31:I40)=0,"",SUM(I31:I40)) -> 10000000 | J42: =IF(SUM(J31:J40)=0,"",SUM(J31:J40)) | K42: =IF(SUM(K31:K40)=0,"",SUM(K31:K40)) | L42: =IF(SUM(L31:L40)=0,"",SUM(L31:L40)) | M42: =IF(SUM(M31:M40)=0,"",SUM(M31:M40)) | ... Q42: =IF(SUM(Q31:Q40)=0,"",SUM(Q31:Q40)) | R42: =SUM(R31:R41) -> 31240000
D44: Footnotes (must be manually asterisked in row D10:D19 and D31:D38)
D45: *
...

Sheet Pro Forma Cap Table
B1: =Inputs!I6 -> Company Name
B2: Pro Forma Capitalization Table
B3: =Inputs!I7 -> 39813
F5: {=IF(TRANSPOSE(Inputs!E$10:E$19)=0,"",TRANSPOSE(Inputs!E$10:E$19))} -> 39113 | G5: 39478 | H5: 39843 | I5: 39843 | J5: 39843 | K5: 39843 | L5: 39843 | M5: 39843 | N5: 39843 | O5: 39843
C6: Common | D6: Stock | E6: Total | F6: {=IF(TRANSPOSE(Inputs!D$10:D$19)=0,"",TRANSPOSE(Inputs!D$10:D$19))} -> Series A | G6: Series B | H6: Series C | I6: Series D | J6: - | K6: - | L6: - | M6: - | N6: - | O6: - | P6: Total | Q6: Total # | R6: Total Ful. Dil | S6: Ful. Dil. as Conv. | T6: Total
B7: Investor (Partner) | C7: =Inputs!K22 -> 1e-08 | D7: =Inputs!K23 -> 1e-07 | E7: Common | F7: {=IF(TRANSPOSE(Inputs!K$10:K$19)=0,0,TRANSPOSE(Inputs!K$10:K$19))} -> 1 | G7: 2 | H7: 2.5 | I7: 2 | J7: 0 | K7: 0 | L7: 0 | M7: 0 | N7: 0 | O7: 0 | P7: Preferred | Q7: Of All | R7: Ownership | S7: Ownership | T7: Dollars ($)
C8: Shares | D8: Options | E8: & Options | F8: =IF(F7=0,"","Preferred") -> Preferred | G8: =IF(G7=0,"","Preferred") -> Preferred | H8: =IF(H7=0,"","Preferred") -> Preferred | I8: =IF(I7=0,"","Preferred") -> Preferred | J8: =IF(J7=0,"","Preferred") | K8: =IF(K7=0,"","Preferred") | L8: =IF(L7=0,"","Preferred") | M8: =IF(M7=0,"","Preferred") | ... O8: =IF(O7=0,"","Preferred") | P8: Shares | Q8: Shares Held | R8: Percent (%) | S8: Percent (%) | T8: Invested
C9: <------------------------------------------------------------------------------------------------------------------- # of Shares ------------------------------------------------------------------------------------------------------------------->
B10: =IF(Inputs!E31=0,Inputs!D31,CONCATENATE(Inputs!D31," (",Inputs!E31,")")) -> HTGC | C10: =IF(C$7="",0,Inputs!P31) -> 0 | D10: =IF(D$7="",0,Inputs!Q31) -> 0 | E10: =SUM(C10:D10) -> 0 | F10: =IF(F$7="",0,Inputs!F31) -> 1000000 | G10: =IF(G$7="",0,Inputs!G31) -> 1000000 | H10: =IF(H$7="",0,Inputs!H31) -> 0 | I10: =IF(I$7="",0,Inputs!I31) -> 0 | J10: =IF(J$7="",0,Inputs!J31) -> 0 | K10: =IF(K$7="",0,Inputs!K31) -> 0 | L10: =IF(L$7="",0,Inputs!L31) -> 0 | M10: =IF(M$7="",0,Inputs!M31) -> 0 | ... O10: =IF(O$7="",0,Inputs!O31) -> 0 | P10: =SUM(F10:O10) -> 2000000 | Q10: =P10+E10 -> 2000000 | R10: =Q10/Q$26 -> 0.064020487 | S10: =(F10*$F$51+G10*$G$51+H10*$H$51+I10*$I$51+J10*$J$51+K10*$K$51+L10*$L$51+M10*$M$51+N10*$N$51+O10*$O$51+E10)/($F$53+$E$26) -> 0.064020487 | T10: =$F$7*F10+$G$7*G10+$H$7*H10+$I$7*I10+$J$7*J10+$K$7*K10+$L$7*L10+$M$7*M10+$N$7*N10+$O$7*O10 -> 3000000
B11: =IF(Inputs!E32=0,Inputs!D32,CONCATENATE(Inputs!D32," (",Inputs!E32,")")) -> Inv B | C11: =IF(C$7="",0,Inputs!P32) -> 0 | D11: =IF(D$7="",0,Inputs!Q32) -> 0 | E11: =SUM(C11:D11) -> 0 | F11: =IF(F$7="",0,Inputs!F32) -> 1000000 | G11: =IF(G$7="",0,Inputs!G32) -> 1000000 | H11: =IF(H$7="",0,Inputs!H32) -> 0 | I11: =IF(I$7="",0,Inputs!I32) -> 0 | J11: =IF(J$7="",0,Inputs!J32) -> 0 | K11: =IF(K$7="",0,Inputs!K32) -> 0 | L11: =IF(L$7="",0,Inputs!L32) -> 0 | M11: =IF(M$7="",0,Inputs!M32) -> 0 | ... O11: =IF(O$7="",0,Inputs!O32) -> 0 | P11: =SUM(F11:O11) -> 2000000 | Q11: =P11+E11 -> 2000000 | R11: =Q11/Q$26 -> 0.064020487 | S11: =(F11*$F$51+G11*$G$51+H11*$H$51+I11*$I$51+J11*$J$51+K11*$K$51+L11*$L$51+M11*$M$51+N11*$N$51+O11*$O$51+E11)/($F$53+$E$26) -> 0.064020487 | T11: =$F$7*F11+$G$7*G11+$H$7*H11+$I$7*I11+$J$7*J11+$K$7*K11+$L$7*L11+$M$7*M11+$N$7*N11+$O$7*O11 -> 3000000
B12: =IF(Inputs!E33=0,Inputs!D33,CONCATENATE(Inputs!D33," (",Inputs!E33,")")) -> Inv C | C12: =IF(C$7="",0,Inputs!P33) -> 0 | D12: =IF(D$7="",0,Inputs!Q33) -> 0 | E12: =SUM(C12:D12) -> 0 | F12: =IF(F$7="",0,Inputs!F33) -> 1000000 | G12: =IF(G$7="",0,Inputs!G33) -> 1000000 | H12: =IF(H$7="",0,Inputs!H33) -> 1000000 | I12: =IF(I$7="",0,Inputs!I33) -> 0 | J12: =IF(J$7="",0,Inputs!J33) -> 0 | K12: =IF(K$7="",0,Inputs!K33) -> 0 | L12: =IF(L$7="",0,Inputs!L33) -> 0 | M12: =IF(M$7="",0,Inputs!M33) -> 0 | ... O12: =IF(O$7="",0,Inputs!O33) -> 0 | P12: =SUM(F12:O12) -> 3000000 | Q12: =P12+E12 -> 3000000 | R12: =Q12/Q$26 -> 0.09603073 | S12: =(F12*$F$51+G12*$G$51+H12*$H$51+I12*$I$51+J12*$J$51+K12*$K$51+L12*$L$51+M12*$M$51+N12*$N$51+O12*$O$51+E12)/($F$53+$E$26) -> 0.09603073 | T12: =$F$7*F12+$G$7*G12+$H$7*H12+$I$7*I12+$J$7*J12+$K$7*K12+$L$7*L12+$M$7*M12+$N$7*N12+$O$7*O12 -> 5500000
B13: =IF(Inputs!E34=0,Inputs!D34,CONCATENATE(Inputs!D34," (",Inputs!E34,")")) -> Inv D | C13: =IF(C$7="",0,Inputs!P34) -> 0 | D13: =IF(D$7="",0,Inputs!Q34) -> 0 | E13: =SUM(C13:D13) -> 0 | F13: =IF(F$7="",0,Inputs!F34) -> 1000000 | G13: =IF(G$7="",0,Inputs!G34) -> 1000000 | H13: =IF(H$7="",0,Inputs!H34) -> 1000000 | I13: =IF(I$7="",0,Inputs!I34) -> 0 | J13: =IF(J$7="",0,Inputs!J34) -> 0 | K13: =IF(K$7="",0,Inputs!K34) -> 0 | L13: =IF(L$7="",0,Inputs!L34) -> 0 | M13: =IF(M$7="",0,Inputs!M34) -> 0 | ... O13: =IF(O$7="",0,Inputs!O34) -> 0 | P13: =SUM(F13:O13) -> 3000000 | Q13: =P13+E13 -> 3000000 | R13: =Q13/Q$26 -> 0.09603073 | S13: =(F13*$F$51+G13*$G$51+H13*$H$51+I13*$I$51+J13*$J$51+K13*$K$51+L13*$L$51+M13*$M$51+N13*$N$51+O13*$O$51+E13)/($F$53+$E$26) -> 0.09603073 | T13: =$F$7*F13+$G$7*G13+$H$7*H13+$I$7*I13+$J$7*J13+$K$7*K13+$L$7*L13+$M$7*M13+$N$7*N13+$O$7*O13 -> 5500000
B14: =IF(Inputs!E35=0,Inputs!D35,CONCATENATE(Inputs!D35," (",Inputs!E35,")")) -> Inv E | C14: =IF(C$7="",0,Inputs!P35) -> 0 | D14: =IF(D$7="",0,Inputs!Q35) -> 0 | E14: =SUM(C14:D14) -> 0 | F14: =IF(F$7="",0,Inputs!F35) -> 1000000 | G14: =IF(G$7="",0,Inputs!G35) -> 1000000 | H14: =IF(H$7="",0,Inputs!H35) -> 1000000 | I14: =IF(I$7="",0,Inputs!I35) -> 0 | J14: =IF(J$7="",0,Inputs!J35) -> 0 | K14: =IF(K$7="",0,Inputs!K35) -> 0 | L14: =IF(L$7="",0,Inputs!L35) -> 0 | M14: =IF(M$7="",0,Inputs!M35) -> 0 | ... O14: =IF(O$7="",0,Inputs!O35) -> 0 | P14: =SUM(F14:O14) -> 3000000 | Q14: =P14+E14 -> 3000000 | R14: =Q14/Q$26 -> 0.09603073 | S14: =(F14*$F$51+G14*$G$51+H14*$H$51+I14*$I$51+J14*$J$51+K14*$K$51+L14*$L$51+M14*$M$51+N14*$N$51+O14*$O$51+E14)/($F$53+$E$26) -> 0.09603073 | T14: =$F$7*F14+$G$7*G14+$H$7*H14+$I$7*I14+$J$7*J14+$K$7*K14+$L$7*L14+$M$7*M14+$N$7*N14+$O$7*O14 -> 5500000
B15: =IF(Inputs!E36=0,Inputs!D36,CONCATENATE(Inputs!D36," (",Inputs!E36,")")) -> Inv F | C15: =IF(C$7="",0,Inputs!P36) -> 0 | D15: =IF(D$7="",0,Inputs!Q36) -> 0 | E15: =SUM(C15:D15) -> 0 | F15: =IF(F$7="",0,Inputs!F36) -> 0 | G15: =IF(G$7="",0,Inputs!G36) -> 0 | H15: =IF(H$7="",0,Inputs!H36) -> 1000000 | I15: =IF(I$7="",0,Inputs!I36) -> 3333333.3 | J15: =IF(J$7="",0,Inputs!J36) -> 0 | K15: =IF(K$7="",0,Inputs!K36) -> 0 | L15: =IF(L$7="",0,Inputs!L36) -> 0 | M15: =IF(M$7="",0,Inputs!M36) -> 0 | ... O15: =IF(O$7="",0,Inputs!O36) -> 0 | P15: =SUM(F15:O15) -> 4333333.3 | Q15: =P15+E15 -> 4333333.3 | R15: =Q15/Q$26 -> 0.13871105 | S15: =(F15*$F$51+G15*$G$51+H15*$H$51+I15*$I$51+J15*$J$51+K15*$K$51+L15*$L$51+M15*$M$51+N15*$N$51+O15*$O$51+E15)/($F$53+$E$26) -> 0.13871105 | T15: =$F$7*F15+$G$7*G15+$H$7*H15+$I$7*I15+$J$7*J15+$K$7*K15+$L$7*L15+$M$7*M15+$N$7*N15+$O$7*O15 -> 9166666.7
B16: =IF(Inputs!E37=0,Inputs!D37,CONCATENATE(Inputs!D37," (",Inputs!E37,")")) -> Inv G | C16: =IF(C$7="",0,Inputs!P37) -> 0 | D16: =IF(D$7="",0,Inputs!Q37) -> 0 | E16: =SUM(C16:D16) -> 0 | F16: =IF(F$7="",0,Inputs!F37) -> 0 | G16: =IF(G$7="",0,Inputs!G37) -> 0 | H16: =IF(H$7="",0,Inputs!H37) -> 1000000 | I16: =IF(I$7="",0,Inputs!I37) -> 3333333.3 | J16: =IF(J$7="",0,Inputs!J37) -> 0 | K16: =IF(K$7="",0,Inputs!K37) -> 0 | L16: =IF(L$7="",0,Inputs!L37) -> 0 | M16: =IF(M$7="",0,Inputs!M37) -> 0 | ... O16: =IF(O$7="",0,Inputs!O37) -> 0 | P16: =SUM(F16:O16) -> 4333333.3 | Q16: =P16+E16 -> 4333333.3 | R16: =Q16/Q$26 -> 0.13871105 | S16: =(F16*$F$51+G16*$G$51+H16*$H$51+I16*$I$51+J16*$J$51+K16*$K$51+L16*$L$51+M16*$M$51+N16*$N$51+O16*$O$51+E16)/($F$53+$E$26) -> 0.13871105 | T16: =$F$7*F16+$G$7*G16+$H$7*H16+$I$7*I16+$J$7*J16+$K$7*K16+$L$7*L16+$M$7*M16+$N$7*N16+$O$7*O16 -> 9166666.7
B17: =IF(Inputs!E38=0,Inputs!D38,CONCATENATE(Inputs!D38," (",Inputs!E38,")")) -> Inv H | C17: =IF(C$7="",0,Inputs!P38) -> 0 | D17: =IF(D$7="",0,Inputs!Q38) -> 0 | E17: =SUM(C17:D17) -> 0 | F17: =IF(F$7="",0,Inputs!F38) -> 0 | G17: =IF(G$7="",0,Inputs!G38) -> 0 | H17: =IF(H$7="",0,Inputs!H38) -> 1000000 | I17: =IF(I$7="",0,Inputs!I38) -> 3333333.3 | J17: =IF(J$7="",0,Inputs!J38) -> 0 | K17: =IF(K$7="",0,Inputs!K38) -> 0 | L17: =IF(L$7="",0,Inputs!L38) -> 0 | M17: =IF(M$7="",0,Inputs!M38) -> 0 | ... O17: =IF(O$7="",0,Inputs!O38) -> 0 | P17: =SUM(F17:O17) -> 4333333.3 | Q17: =P17+E17 -> 4333333.3 | R17: =Q17/Q$26 -> 0.13871105 | S17: =(F17*$F$51+G17*$G$51+H17*$H$51+I17*$I$51+J17*$J$51+K17*$K$51+L17*$L$51+M17*$M$51+N17*$N$51+O17*$O$51+E17)/($F$53+$E$26) -> 0.13871105 | T17: =$F$7*F17+$G$7*G17+$H$7*H17+$I$7*I17+$J$7*J17+$K$7*K17+$L$7*L17+$M$7*M17+$N$7*N17+$O$7*O17 -> 9166666.7
B18: =Inputs!D39 -> Other Investors | C18: =IF(C$7="",0,Inputs!P39) -> 0 | D18: =IF(D$7="",0,Inputs!Q39) -> 0 | E18: =SUM(C18:D18) -> 0 | F18: =IF(F$7="",0,Inputs!F39) -> 0 | G18: =IF(G$7="",0,Inputs!G39) -> 0 | H18: =IF(H$7="",0,Inputs!H39) -> 0 | I18: =IF(I$7="",0,Inputs!I39) -> 0 | J18: =IF(J$7="",0,Inputs!J39) -> 0 | K18: =IF(K$7="",0,Inputs!K39) -> 0 | L18: =IF(L$7="",0,Inputs!L39) -> 0 | M18: =IF(M$7="",0,Inputs!M39) -> 0 | ... O18: =IF(O$7="",0,Inputs!O39) -> 0 | P18: =SUM(F18:O18) -> 0 | Q18: =P18+E18 -> 0 | R18: =Q18/Q$26 -> 0 | S18: =(F18*$F$51+G18*$G$51+H18*$H$51+I18*$I$51+J18*$J$51+K18*$K$51+L18*$L$51+M18*$M$51+N18*$N$51+O18*$O$51+E18)/($F$53+$E$26) -> 0 | T18: =$F$7*F18+$G$7*G18+$H$7*H18+$I$7*I18+$J$7*J18+$K$7*K18+$L$7*L18+$M$7*M18+$N$7*N18+$O$7*O18 -> 0
B19: Warrants By Series | C19: =Inputs!N22 -> 0 | D19: =Inputs!N23 -> 0 | E19: =SUM(C19:D19) -> 0 | F19: {=IF(TRANSPOSE(Inputs!N$10:N$19)=0,0,TRANSPOSE(Inputs!N$10:N$19))} -> 10000 | G19: 10000 | H19: 10000 | I19: 10000 | J19: 0 | K19: 0 | L19: 0 | M19: 0 | N19: 0 | O19: 0 | P19: =SUM(F19:O19) -> 40000 | Q19: =P19+E19 -> 40000 | R19: =Q19/Q$26 -> 0.0012804097 | S19: =(F19*$F$51+G19*$G$51+H19*$H$51+I19*$I$51+J19*$J$51+K19*$K$51+L19*$L$51+M19*$M$51+N19*$N$51+O19*$O$51+E19)/($F$53+$E$26) -> 0.0012804097 | T19: =T38 -> 40000
B20: Subtotal Investors | C20: =SUM(C10:C18) -> 0 | D20: =SUM(D10:D18) -> 0 | E20: =SUM(E10:E18) -> 0 | F20: =SUM(F10:F19) -> 5010000 | G20: =SUM(G10:G19) -> 5010000 | H20: =SUM(H10:H19) -> 6010000 | I20: =SUM(I10:I19) -> 10010000 | J20: =SUM(J10:J19) -> 0 | K20: =SUM(K10:K19) -> 0 | L20: =SUM(L10:L19) -> 0 | M20: =SUM(M10:M19) -> 0 | ... T20: =SUM(T10:T19) -> 50040000
B22: =Inputs!D40 -> Management | C22: =IF(C$7=0,0,Inputs!P40) -> 5200000 | D22: =IF(D$7=0,0,Inputs!Q40) -> 0 | E22: =SUM(C22:D22) -> 5200000 | P22: =SUM(F22:O22) -> 0 | Q22: =P22+E22 -> 5200000 | R22: =Q22/Q$26 -> 0.16645327 | S22: =(F22*$F$51+G22*$G$51+H22*$H$51+I22*$I$51+J22*$J$51+K22*$K$51+L22*$L$51+M22*$M$51+N22*$N$51+O22*$O$51+E22)/($F$53+$E$26) -> 0.16645327 | T22: =$F$7*F22+$G$7*G22+$H$7*H22+$I$7*I22+$J$7*J22+$K$7*K22+$L$7*L22+$M$7*M22+$N$7*N22+$O$7*O22 -> 0
B24: Subtotal Managers | C24: =SUM(C22:C23) -> 5200000 | D24: =SUM(D22:D23) -> 0 | E24: =SUM(E22:E23) -> 5200000 | F24: =SUM(F22:F23) -> 0 | G24: =SUM(G22:G23) -> 0 | H24: =SUM(H22:H23) -> 0 | I24: =SUM(I22:I23) -> 0 | J24: =SUM(J22:J23) -> 0 | ... T24: =SUM(T22:T23) -> 0
B26: Total Shares | C26: =C20+C24 -> 5200000 | D26: =D20+D24 -> 0 | E26: =E20+E24 -> 5200000 | F26: =F20+F24 -> 5010000 | G26: =G20+G24 -> 5010000 | H26: =H20+H24 -> 6010000 | I26: =I20+I24 -> 10010000 | J26: =J20+J24 -> 0 | ... S26: =S20+S24 -> 1
C28: <--------------------------------------------------------------------------------------------------------------- Amount Invested --------------------------------------------------------------------------------------------------------------->
B29: =IF(Inputs!E31=0,Inputs!D31,CONCATENATE(Inputs!D31," (",Inputs!E31,")")) -> HTGC | C29: =IF(C$7="","",Inputs!P31*C$7) -> 0 | D29: =IF(D$7="","",Inputs!Q31*D$7) -> 0 | E29: =SUM(C29:D29) -> 0 | F29: =IF(F$7="","",Inputs!F31*F$7) -> 1000000 | G29: =IF(G$7="","",Inputs!G31*G$7) -> 2000000 | H29: =IF(H$7="","",Inputs!H31*H$7) -> 0 | I29: =IF(I$7="","",Inputs!I31*I$7) -> 0 | J29: =IF(J$7="","",Inputs!J31*J$7) -> 0 | K29: =IF(K$7="","",Inputs!K31*K$7) -> 0 | L29: =IF(L$7="","",Inputs!L31*L$7) -> 0 | M29: =IF(M$7="","",Inputs!M31*M$7) -> 0 | ... O29: =IF(O$7="","",Inputs!O31*O$7) -> 0 | P29: =SUM(F29:O29) -> 3000000 | Q29: ='Pro Forma Cap Table'!Q10 -> 2000000 | R29: =Q29/$Q$26 -> 0.064020487 | S29: ='Pro Forma Cap Table'!S10 -> 0.064020487 | T29: =SUM(F29:O29) -> 3000000
B30: =IF(Inputs!E32=0,Inputs!D32,CONCATENATE(Inputs!D32," (",Inputs!E32,")")) -> Inv B | C30: =IF(C$7="","",Inputs!P32*C$7) -> 0 | D30: =IF(D$7="","",Inputs!Q32*D$7) -> 0 | E30: =SUM(C30:D30) -> 0 | F30: =IF(F$7="","",Inputs!F32*F$7) -> 1000000 | G30: =IF(G$7="","",Inputs!G32*G$7) -> 2000000 | H30: =IF(H$7="","",Inputs!H32*H$7) -> 0 | I30: =IF(I$7="","",Inputs!I32*I$7) -> 0 | J30: =IF(J$7="","",Inputs!J32*J$7) -> 0 | K30: =IF(K$7="","",Inputs!K32*K$7) -> 0 | L30: =IF(L$7="","",Inputs!L32*L$7) -> 0 | M30: =IF(M$7="","",Inputs!M32*M$7) -> 0 | ... O30: =IF(O$7="","",Inputs!O32*O$7) -> 0 | P30: =SUM(F30:O30) -> 3000000 | Q30: ='Pro Forma Cap Table'!Q11 -> 2000000 | R30: =Q30/$Q$26 -> 0.064020487 | S30: ='Pro Forma Cap Table'!S11 -> 0.064020487 | T30: =SUM(F30:O30) -> 3000000
B31: =IF(Inputs!E33=0,Inputs!D33,CONCATENATE(Inputs!D33," (",Inputs!E33,")")) -> Inv C | C31: =IF(C$7="","",Inputs!P33*C$7) -> 0 | D31: =IF(D$7="","",Inputs!Q33*D$7) -> 0 | E31: =SUM(C31:D31) -> 0 | F31: =IF(F$7="","",Inputs!F33*F$7) -> 1000000 | G31: =IF(G$7="","",Inputs!G33*G$7) -> 2000000 | H31: =IF(H$7="","",Inputs!H33*H$7) -> 2500000 | I31: =IF(I$7="","",Inputs!I33*I$7) -> 0 | J31: =IF(J$7="","",Inputs!J33*J$7) -> 0 | K31: =IF(K$7="","",Inputs!K33*K$7) -> 0 | L31: =IF(L$7="","",Inputs!L33*L$7) -> 0 | M31: =IF(M$7="","",Inputs!M33*M$7) -> 0 | ... O31: =IF(O$7="","",Inputs!O33*O$7) -> 0 | P31: =SUM(F31:O31) -> 5500000 | Q31: ='Pro Forma Cap Table'!Q12 -> 3000000 | R31: =Q31/$Q$26 -> 0.09603073 | S31: ='Pro Forma Cap Table'!S12 -> 0.09603073 | T31: =SUM(F31:O31) -> 5500000
B32: =IF(Inputs!E34=0,Inputs!D34,CONCATENATE(Inputs!D34," (",Inputs!E34,")")) -> Inv D | C32: =IF(C$7="","",Inputs!P34*C$7) -> 0 | D32: =IF(D$7="","",Inputs!Q34*D$7) -> 0 | E32: =SUM(C32:D32) -> 0 | F32: =IF(F$7="","",Inputs!F34*F$7) -> 1000000 | G32: =IF(G$7="","",Inputs!G34*G$7) -> 2000000 | H32: =IF(H$7="","",Inputs!H34*H$7) -> 2500000 | I32: =IF(I$7="","",Inputs!I34*I$7) -> 0 | J32: =IF(J$7="","",Inputs!J34*J$7) -> 0 | K32: =IF(K$7="","",Inputs!K34*K$7) -> 0 | L32: =IF(L$7="","",Inputs!L34*L$7) -> 0 | M32: =IF(M$7="","",Inputs!M34*M$7) -> 0 | ... O32: =IF(O$7="","",Inputs!O34*O$7) -> 0 | P32: =SUM(F32:O32) -> 5500000 | Q32: ='Pro Forma Cap Table'!Q13 -> 3000000 | R32: =Q32/$Q$26 -> 0.09603073 | S32: ='Pro Forma Cap Table'!S13 -> 0.09603073 | T32: =SUM(F32:O32) -> 5500000
B33: =IF(Inputs!E35=0,Inputs!D35,CONCATENATE(Inputs!D35," (",Inputs!E35,")")) -> Inv E | C33: =IF(C$7="","",Inputs!P35*C$7) -> 0 | D33: =IF(D$7="","",Inputs!Q35*D$7) -> 0 | E33: =SUM(C33:D33) -> 0 | F33: =IF(F$7="","",Inputs!F35*F$7) -> 1000000 | G33: =IF(G$7="","",Inputs!G35*G$7) -> 2000000 | H33: =IF(H$7="","",Inputs!H35*H$7) -> 2500000 | I33: =IF(I$7="","",Inputs!I35*I$7) -> 0 | J33: =IF(J$7="","",Inputs!J35*J$7) -> 0 | K33: =IF(K$7="","",Inputs!K35*K$7) -> 0 | L33: =IF(L$7="","",Inputs!L35*L$7) -> 0 | M33: =IF(M$7="","",Inputs!M35*M$7) -> 0 | ... O33: =IF(O$7="","",Inputs!O35*O$7) -> 0 | P33: =SUM(F33:O33) -> 5500000 | Q33: ='Pro Forma Cap Table'!Q14 -> 3000000 | R33: =Q33/$Q$26 -> 0.09603073 | S33: ='Pro Forma Cap Table'!S14 -> 0.09603073 | T33: =SUM(F33:O33) -> 5500000
B34: =IF(Inputs!E36=0,Inputs!D36,CONCATENATE(Inputs!D36," (",Inputs!E36,")")) -> Inv F | C34: =IF(C$7="","",Inputs!P36*C$7) -> 0 | D34: =IF(D$7="","",Inputs!Q36*D$7) -> 0 | E34: =SUM(C34:D34) -> 0 | F34: =IF(F$7="","",Inputs!F36*F$7) -> 0 | G34: =IF(G$7="","",Inputs!G36*G$7) -> 0 | H34: =IF(H$7="","",Inputs!H36*H$7) -> 2500000 | I34: =IF(I$7="","",Inputs!I36*I$7) -> 6666666.7 | J34: =IF(J$7="","",Inputs!J36*J$7) -> 0 | K34: =IF(K$7="","",Inputs!K36*K$7) -> 0 | L34: =IF(L$7="","",Inputs!L36*L$7) -> 0 | M34: =IF(M$7="","",Inputs!M36*M$7) -> 0 | ... O34: =IF(O$7="","",Inputs!O36*O$7) -> 0 | P34: =SUM(F34:O34) -> 9166666.7 | Q34: ='Pro Forma Cap Table'!Q15 -> 4333333.3 | R34: =Q34/$Q$26 -> 0.13871105 | S34: ='Pro Forma Cap Table'!S15 -> 0.13871105 | T34: =SUM(F34:O34) -> 9166666.7
B35: =IF(Inputs!E37=0,Inputs!D37,CONCATENATE(Inputs!D37," (",Inputs!E37,")")) -> Inv G | C35: =IF(C$7="","",Inputs!P37*C$7) -> 0 | D35: =IF(D$7="","",Inputs!Q37*D$7) -> 0 | E35: =SUM(C35:D35) -> 0 | F35: =IF(F$7="","",Inputs!F37*F$7) -> 0 | G35: =IF(G$7="","",Inputs!G37*G$7) -> 0 | H35: =IF(H$7="","",Inputs!H37*H$7) -> 2500000 | I35: =IF(I$7="","",Inputs!I37*I$7) -> 6666666.7 | J35: =IF(J$7="","",Inputs!J37*J$7) -> 0 | K35: =IF(K$7="","",Inputs!K37*K$7) -> 0 | L35: =IF(L$7="","",Inputs!L37*L$7) -> 0 | M35: =IF(M$7="","",Inputs!M37*M$7) -> 0 | ... O35: =IF(O$7="","",Inputs!O37*O$7) -> 0 | P35: =SUM(F35:O35) -> 9166666.7 | Q35: ='Pro Forma Cap Table'!Q16 -> 4333333.3 | R35: =Q35/$Q$26 -> 0.13871105 | S35: ='Pro Forma Cap Table'!S16 -> 0.13871105 | T35: =SUM(F35:O35) -> 9166666.7
B36: =IF(Inputs!E38=0,Inputs!D38,CONCATENATE(Inputs!D38," (",Inputs!E38,")")) -> Inv H | C36: =IF(C$7="","",Inputs!P38*C$7) -> 0 | D36: =IF(D$7="","",Inputs!Q38*D$7) -> 0 | E36: =SUM(C36:D36) -> 0 | F36: =IF(F$7="","",Inputs!F38*F$7) -> 0 | G36: =IF(G$7="","",Inputs!G38*G$7) -> 0 | H36: =IF(H$7="","",Inputs!H38*H$7) -> 2500000 | I36: =IF(I$7="","",Inputs!I38*I$7) -> 6666666.7 | J36: =IF(J$7="","",Inputs!J38*J$7) -> 0 | K36: =IF(K$7="","",Inputs!K38*K$7) -> 0 | L36: =IF(L$7="","",Inputs!L38*L$7) -> 0 | M36: =IF(M$7="","",Inputs!M38*M$7) -> 0 | ... O36: =IF(O$7="","",Inputs!O38*O$7) -> 0 | P36: =SUM(F36:O36) -> 9166666.7 | Q36: ='Pro Forma Cap Table'!Q17 -> 4333333.3 | R36: =Q36/$Q$26 -> 0.13871105 | S36: ='Pro Forma Cap Table'!S17 -> 0.13871105 | T36: =SUM(F36:O36) -> 9166666.7
B37: =Inputs!D39 -> Other Investors | C37: =IF(C$7="","",Inputs!P39*C$7) -> 0 | D37: =IF(D$7="","",Inputs!Q39*D$7) -> 0 | E37: =SUM(C37:D37) -> 0 | F37: =IF(F$7="","",Inputs!F39*F$7) -> 0 | G37: =IF(G$7="","",Inputs!G39*G$7) -> 0 | H37: =IF(H$7="","",Inputs!H39*H$7) -> 0 | I37: =IF(I$7="","",Inputs!I39*I$7) -> 0 | J37: =IF(J$7="","",Inputs!J39*J$7) -> 0 | K37: =IF(K$7="","",Inputs!K39*K$7) -> 0 | L37: =IF(L$7="","",Inputs!L39*L$7) -> 0 | M37: =IF(M$7="","",Inputs!M39*M$7) -> 0 | ... O37: =IF(O$7="","",Inputs!O39*O$7) -> 0 | P37: =SUM(F37:O37) -> 0 | Q37: ='Pro Forma Cap Table'!Q18 -> 0 | R37: =Q37/$Q$26 -> 0 | S37: ='Pro Forma Cap Table'!S18 -> 0 | T37: =SUM(F37:O37) -> 0
B38: Warrants By Series | C38: =C19*Inputs!$K$20 -> 0 | D38: =D19*Inputs!$K$20 -> 0 | F38: =F19*Inputs!O10 -> 10000 | G38: =G19*Inputs!$O11 -> 10000 | H38: =H19*Inputs!$O12 -> 10000 | I38: =I19*Inputs!$O13 -> 10000 | J38: =J19*Inputs!$O14 -> 0 | K38: =K19*Inputs!$O15 -> 0 | L38: =L19*Inputs!$O16 -> 0 | M38: =M19*Inputs!$O17 -> 0 | N38: =N19*Inputs!$O18 -> 0 | O38: =O19*Inputs!$O19 -> 0 | P38: =SUM(F38:O38) -> 40000 | Q38: ='Pro Forma Cap Table'!Q19 -> 40000 | R38: =Q38/$Q$26 -> 0.0012804097 | S38: ='Pro Forma Cap Table'!S19 -> 0.0012804097 | T38: =SUM(F38:O38) -> 40000
B39: Subtotal Investors | C39: =SUM(C29:C37) -> 0 | D39: =SUM(D29:D37) -> 0 | E39: =SUM(E29:E37) -> 0 | F39: =SUM(F29:F38) -> 5010000 | G39: =SUM(G29:G38) -> 10010000 | H39: =SUM(H29:H38) -> 15010000 | I39: =SUM(I29:I38) -> 20010000 | J39: =SUM(J29:J38) -> 0 | K39: =SUM(K29:K38) -> 0 | L39: =SUM(L29:L38) -> 0 | M39: =SUM(M29:M38) -> 0 | ... T39: =SUM(T29:T38) -> 50040000
B41: =Inputs!D40 -> Management | C41: =IF(C$7=0,0,Inputs!M22*C7) -> 0.052 | D41: =IF(D$7=0,0,Inputs!M23*D7) -> 0 | E41: =SUM(C41:D41) -> 0.052 | F41: =IF(F$7=0,0,Inputs!F40*F$7) -> 0 | G41: =IF(G$7=0,0,Inputs!G40*G$7) -> 0 | H41: =IF(H$7=0,0,Inputs!H40*H$7) -> 0 | I41: =IF(I$7=0,0,Inputs!I40*I$7) -> 0 | J41: =IF(J$7=0,0,Inputs!J40*J$7) -> 0 | K41: =IF(K$7=0,0,Inputs!K40*K$7) -> 0 | L41: =IF(L$7=0,0,Inputs!L40*L$7) -> 0 | M41: =IF(M$7=0,0,Inputs!M40*M$7) -> 0 | ... O41: =IF(O$7=0,0,Inputs!O40*O$7) -> 0 | P41: =SUM(F41:O41) -> 0 | Q41: =Q22 -> 5200000 | R41: =Q41/Q$26 -> 0.16645327 | S41: ='Pro Forma Cap Table'!S22 -> 0.16645327 | T41: =T22 -> 0
B43: Subtotal Managers | C43: =SUM(C41:C42) -> 0.052 | D43: =SUM(D41:D42) -> 0 | E43: =SUM(E41:E42) -> 0.052 | F43: =SUM(F41:F42) -> 0 | G43: =SUM(G41:G42) -> 0 | H43: =SUM(H41:H42) -> 0 | I43: =SUM(I41:I42) -> 0 | J43: =SUM(J41:J42) -> 0 | ... T43: =SUM(T41:T42) -> 0
B45: Total Dollars | C45: =C91*C7 -> 0.052 | D45: =D91*D7 -> 0 | E45: =SUM(C45:D45) -> 0.052 | F45: =IF(F7=0,"N/A",F$91*F$7) -> 5000000 | G45: =IF(G7=0,"N/A",G$91*G$7) -> 10000000 | H45: =IF(H7=0,"N/A",H$91*H$7) -> 15000000 | I45: =IF(I7=0,"N/A",I$91*I$7) -> 20000000 | J45: =IF(J7=0,"N/A",J$91*J$7) -> N/A | K45: =IF(K7=0,"N/A",K$91*K$7) -> N/A | L45: =IF(L7=0,"N/A",L$91*L$7) -> N/A | M45: =IF(M7=0,"N/A",M$91*M$7) -> N/A | ... O45: =IF(O7=0,"N/A",O$91*O$7) -> N/A | P45: =SUM(F45:O45) -> 50000000 | R45: =R39+R43 -> 1 | S45: =S39+S43 -> 1 | T45: =T39+T43 -> 50040000
D46: Post-Money | F46: {=IF(TRANSPOSE(Inputs!F$10:F$19)=0,"N/A",TRANSPOSE(Inputs!F$10:F$19))} -> N/A | G46: N/A | H46: N/A | I46: N/A | J46: N/A | K46: N/A | L46: N/A | M46: N/A | N46: N/A | O46: N/A | Q46: Total Liquidation Preference | T46: =F92*F47+G92*G47+H92*H47+I92*I47+J92*J47+K92*K47+L92*L47+M92*M47+N92*N47+O92*O47 -> 50000000
D47: Liq. Pref. Multiple | F47: {=IF(TRANSPOSE(Inputs!G$10:G$19)=0,0,TRANSPOSE(Inputs!G$10:G$19))} -> 1 | G47: 1 | H47: 1 | I47: 1 | J47: 1 | K47: 1 | L47: 1 | M47: 1 | N47: 1 | O47: 1 | Q47: =IF(G7=0,F6,IF(H7=0,G6,IF(I7=0,H6,IF(J7=0,I6,IF(K7=0,J6,IF(L7=0,K6,IF(M7=0,L6,IF(N7=0,M6,IF(O7=0,N6,O6))))))))) -> Series D | R47: ful. dil. post-money valuation of | T47: =R48*Q26 -> 62480000
D48: Cap | F48: {=IF(TRANSPOSE(Inputs!H$10:H$19)=0,0,TRANSPOSE(Inputs!H$10:H$19))} -> 2 | G48: 2 | H48: 2 | I48: 2 | J48: 2 | K48: 2 | L48: 2 | M48: 2 | N48: 2 | O48: 2 | Q48: Based on | R48: =IF(G7=0,F7,IF(H7=0,G7,IF(I7=0,H7,IF(J7=0,I7,IF(K7=0,J7,IF(L7=0,K7,IF(M7=0,L7,IF(N7=0,M7,IF(O7=0,N7,O7))))))))) -> 2 | S48: per share price.
...

Sheet $-Pro Forma Cap Table
B1: =Inputs!I6 -> Company Name
B2: Pro Forma Capitalization Table
F5: {=IF(TRANSPOSE(Inputs!E$10:E$19)=0,"",TRANSPOSE(Inputs!E$10:E$19))} -> 39113 | G5: 39478 | H5: 39843 | I5: 39843 | J5: 39843 | K5: 39843 | L5: 39843 | M5: 39843 | N5: 39843 | O5: 39843
D31: Post-Money | F31: {=IF(TRANSPOSE(Inputs!F$10:F$19)=0,"N/A",TRANSPOSE(Inputs!F$10:F$19))} -> N/A | G31: N/A | H31: N/A | I31: N/A | J31: N/A | K31: N/A | L31: N/A | M31: N/A | N31: N/A | O31: N/A | R31: =IF('Pro Forma Cap Table'!#REF!=0,'Pro Forma Cap Table'!#REF!,IF('Pro Forma Cap Table'!#REF!=0,'Pro Forma Cap Table'!#REF!,IF('Pro Forma Cap Table'!#REF!=0,'Pro Forma Cap Table'!#REF!,IF('Pro Forma Cap Table'!#REF!=0,'Pro Forma Cap Table'!#REF!,IF('Pro Forma Cap Table'!#REF!=0,'Pro Forma Cap Table'!#REF!,IF('Pro Forma Cap Table'!#REF!=0,'Pro Forma Cap Table'!#REF!,IF('Pro Forma Cap Table'!#REF!=0,'Pro Forma Cap Table'!#REF!,IF('Pro Forma Cap Table'!#REF!=0,'Pro Forma Cap Table'!#REF!,IF('Pro Forma Cap Table'!#REF!=0,'Pro Forma Cap Table'!#REF!,'Pro Forma Cap Table'!#REF!))))))))) -> #REF! | S31: Post-Money Valuation of | U31: =S32*'Pro Forma Cap Table'!Q91 -> #REF!
D32: Preference Multiple | F32: {=IF(TRANSPOSE(Inputs!G$10:G$19)=0,"",TRANSPOSE(Inputs!G$10:G$19))} -> 1 | G32: 1 | H32: 1 | I32: 1 | J32: 1 | K32: 1 | L32: 1 | M32: 1 | N32: 1 | O32: 1 | R32: Based on | S32: =IF('Pro Forma Cap Table'!#REF!=0,'Pro Forma Cap Table'!#REF!,IF('Pro Forma Cap Table'!#REF!=0,'Pro Forma Cap Table'!#REF!,IF('Pro Forma Cap Table'!#REF!=0,'Pro Forma Cap Table'!#REF!,IF('Pro Forma Cap Table'!#REF!=0,'Pro Forma Cap Table'!#REF!,IF('Pro Forma Cap Table'!#REF!=0,'Pro Forma Cap Table'!#REF!,IF('Pro Forma Cap Table'!#REF!=0,'Pro Forma Cap Table'!#REF!,IF('Pro Forma Cap Table'!#REF!=0,'Pro Forma Cap Table'!#REF!,IF('Pro Forma Cap Table'!#REF!=0,'Pro Forma Cap Table'!#REF!,IF('Pro Forma Cap Table'!#REF!=0,'Pro Forma Cap Table'!#REF!,'Pro Forma Cap Table'!#REF!))))))))) -> #REF! | T32: per share price.
D33: Cap | F33: {=IF(TRANSPOSE(Inputs!H$10:H$19)=0,"",TRANSPOSE(Inputs!H$10:H$19))} -> 2 | G33: 2 | H33: 2 | I33: 2 | J33: 2 | K33: 2 | L33: 2 | M33: 2 | N33: 2 | O33: 2
D34: Participating Preferred | F34: =IF(F32="","",IF(F33<=F32,"No","Yes")) -> Yes | G34: =IF(G32="","",IF(G33<=G32,"No","Yes")) -> Yes | H34: =IF(H32="","",IF(H33<=H32,"No","Yes")) -> Yes | I34: =IF(I32="","",IF(I33<=I32,"No","Yes")) -> Yes | J34: =IF(J32="","",IF(J33<=J32,"No","Yes")) -> Yes | K34: =IF(K32="","",IF(K33<=K32,"No","Yes")) -> Yes | L34: =IF(L32="","",IF(L33<=L32,"No","Yes")) -> Yes | M34: =IF(M32="","",IF(M33<=M32,"No","Yes")) -> Yes | ... O34: =IF(O32="","",IF(O33<=O32,"No","Yes")) -> Yes | R34: Footnotes
D35: Seniority Rank | F35: {=IF(TRANSPOSE(Inputs!I$10:I$19)=0,"",TRANSPOSE(Inputs!I$10:I$19))} -> 10 | G35: 10 | H35: 2 | I35: 1 | J35: 10 | K35: 10 | L35: 10 | M35: 10 | N35: 10 | O35: 10 | R35: =IF(Inputs!E45="Text Here","HIDE ROW", CONCATENATE(Inputs!D45, Inputs!E45)) -> *
D36: Conversion Ratio | F36: {=IF(TRANSPOSE(Inputs!J$10:J$19)=0,0,TRANSPOSE(Inputs!J$10:J$19))} -> 1 | G36: 1 | H36: 1 | I36: 1 | J36: 1 | K36: 1 | L36: 1 | M36: 1 | N36: 1 | O36: 1 | R36: =IF(Inputs!E46="Text Here","HIDE ROW", CONCATENATE(Inputs!D46, Inputs!E46)) -> **
D37: Round CSE | F37: =IFERROR(F36*'Pro Forma Cap Table'!F91,"") -> 5000000 | G37: =IFERROR(G36*'Pro Forma Cap Table'!G91,"") -> 5000000 | H37: =IFERROR(H36*'Pro Forma Cap Table'!H91,"") -> 6000000 | I37: =IFERROR(I36*'Pro Forma Cap Table'!I91,"") -> 10000000 | J37: =IFERROR(J36*'Pro Forma Cap Table'!J91,"") -> 0 | K37: =IFERROR(K36*'Pro Forma Cap Table'!K91,"") -> 0 | L37: =IFERROR(L36*'Pro Forma Cap Table'!L91,"") -> 0 | M37: =IFERROR(M36*'Pro Forma Cap Table'!M91,"") -> 0 | ... O37: =IFERROR(O36*'Pro Forma Cap Table'!O91,"") -> 0 | P37: =SUM(F37:O37) -> 26000000 | R37: =IF(Inputs!E47="Text Here","HIDE ROW", CONCATENATE(Inputs!D47," ",Inputs!E47)) -> ***
D38: in % | F38: =F37/(F37+'Pro Forma Cap Table'!$Q$43) -> 0.49019608 | G38: =G37/(G37+'Pro Forma Cap Table'!$Q$43) -> 0.49019608 | H38: =H37/(H37+'Pro Forma Cap Table'!$Q$43) -> 0.53571429 | I38: =I37/(I37+'Pro Forma Cap Table'!$Q$43) -> 0.65789474 | J38: =J37/(J37+'Pro Forma Cap Table'!$Q$43) -> 0 | K38: =K37/(K37+'Pro Forma Cap Table'!$Q$43) -> 0 | L38: =L37/(L37+'Pro Forma Cap Table'!$Q$43) -> 0 | M38: =M37/(M37+'Pro Forma Cap Table'!$Q$43) -> 0 | ... O38: =O37/(O37+'Pro Forma Cap Table'!$Q$43) -> 0 | R38: =IF(Inputs!E48="Text Here","HIDE ROW", CONCATENATE(Inputs!D48," ",Inputs!E48)) -> ****

Sheet Waterfall
B1: =Inputs!I6 -> Company Name
B2: Pro Forma Capitalization Table
B3: =Inputs!I7 -> 39813
F5: {=IF(TRANSPOSE(Inputs!E$10:E$19)=0,"",TRANSPOSE(Inputs!E$10:E$19))} -> 39113 | G5: 39478 | H5: 39843 | I5: 39843 | J5: 39843 | K5: 39843 | L5: 39843 | M5: 39843 | N5: 39843 | O5: 39843
C6: Common | D6: Stock | E6: Total | F6: {=IF(TRANSPOSE(Inputs!D$10:D$19)=0,"",TRANSPOSE(Inputs!D$10:D$19))} -> Series A | G6: Series B | H6: Series C | I6: Series D | J6: - | K6: - | L6: - | M6: - | N6: - | O6: - | P6: Total | Q6: Total # | R6: Total Ful. Dil | S6: Ful. Dil. as Conv. | T6: Total
B7: Investor (Partner) | C7: =Inputs!K22 -> 1e-08 | D7: =Inputs!K23 -> 1e-07 | E7: Common | F7: {=IF(TRANSPOSE(Inputs!K$10:K$19)=0,0,TRANSPOSE(Inputs!K$10:K$19))} -> 1 | G7: 2 | H7: 2.5 | I7: 2 | J7: 0 | K7: 0 | L7: 0 | M7: 0 | N7: 0 | O7: 0 | P7: Preferred | Q7: Of All | R7: Ownership | S7: Ownership | T7: Dollars ($)
C8: Shares | D8: Options | E8: & Options | F8: =IF(F7=0,"","Preferred") -> Preferred | G8: =IF(G7=0,"","Preferred") -> Preferred | H8: =IF(H7=0,"","Preferred") -> Preferred | I8: =IF(I7=0,"","Preferred") -> Preferred | J8: =IF(J7=0,"","Preferred") | K8: =IF(K7=0,"","Preferred") | L8: =IF(L7=0,"","Preferred") | M8: =IF(M7=0,"","Preferred") | ... O8: =IF(O7=0,"","Preferred") | P8: Shares | Q8: Shares Held | R8: Percent (%) | S8: Percent (%) | T8: Invested
C9: <------------------------------------------------------------------------------------------------------------------- # of Shares ------------------------------------------------------------------------------------------------------------------->
B10: =IF(Inputs!E31=0,Inputs!D31,CONCATENATE(Inputs!D31," (",Inputs!E31,")")) -> HTGC | C10: =IF(C$7="",0,Inputs!P31) -> 0 | D10: =IF(D$7="",0,Inputs!Q31) -> 0 | E10: =SUM(C10:D10) -> 0 | F10: =IF(F$7="",0,Inputs!F31) -> 1000000 | G10: =IF(G$7="",0,Inputs!G31) -> 1000000 | H10: =IF(H$7="",0,Inputs!H31) -> 0 | I10: =IF(I$7="",0,Inputs!I31) -> 0 | J10: =IF(J$7="",0,Inputs!J31) -> 0 | K10: =IF(K$7="",0,Inputs!K31) -> 0 | L10: =IF(L$7="",0,Inputs!L31) -> 0 | M10: =IF(M$7="",0,Inputs!M31) -> 0 | ... O10: =IF(O$7="",0,Inputs!O31) -> 0 | P10: =SUM(F10:O10) -> 2000000 | Q10: =P10+E10 -> 2000000 | R10: =Q10/Q$26 -> 0.064020487 | S10: =(F10*$F$51+G10*$G$51+H10*$H$51+I10*$I$51+J10*$J$51+K10*$K$51+L10*$L$51+M10*$M$51+N10*$N$51+O10*$O$51+E10)/($F$53+$E$26) -> 0.036182723 | T10: =$F$7*F10+$G$7*G10+$H$7*H10+$I$7*I10+$J$7*J10+$K$7*K10+$L$7*L10+$M$7*M10+$N$7*N10+$O$7*O10 -> 3000000
B11: =IF(Inputs!E32=0,Inputs!D32,CONCATENATE(Inputs!D32," (",Inputs!E32,")")) -> Inv B | C11: =IF(C$7="",0,Inputs!P32) -> 0 | D11: =IF(D$7="",0,Inputs!Q32) -> 0 | E11: =SUM(C11:D11) -> 0 | F11: =IF(F$7="",0,Inputs!F32) -> 1000000 | G11: =IF(G$7="",0,Inputs!G32) -> 1000000 | H11: =IF(H$7="",0,Inputs!H32) -> 0 | I11: =IF(I$7="",0,Inputs!I32) -> 0 | J11: =IF(J$7="",0,Inputs!J32) -> 0 | K11: =IF(K$7="",0,Inputs!K32) -> 0 | L11: =IF(L$7="",0,Inputs!L32) -> 0 | M11: =IF(M$7="",0,Inputs!M32) -> 0 | ... O11: =IF(O$7="",0,Inputs!O32) -> 0 | P11: =SUM(F11:O11) -> 2000000 | Q11: =P11+E11 -> 2000000 | R11: =Q11/Q$26 -> 0.064020487 | S11: =(F11*$F$51+G11*$G$51+H11*$H$51+I11*$I$51+J11*$J$51+K11*$K$51+L11*$L$51+M11*$M$51+N11*$N$51+O11*$O$51+E11)/($F$53+$E$26) -> 0.036182723 | T11: =$F$7*F11+$G$7*G11+$H$7*H11+$I$7*I11+$J$7*J11+$K$7*K11+$L$7*L11+$M$7*M11+$N$7*N11+$O$7*O11 -> 3000000
B12: =IF(Inputs!E33=0,Inputs!D33,CONCATENATE(Inputs!D33," (",Inputs!E33,")")) -> Inv C | C12: =IF(C$7="",0,Inputs!P33) -> 0 | D12: =IF(D$7="",0,Inputs!Q33) -> 0 | E12: =SUM(C12:D12) -> 0 | F12: =IF(F$7="",0,Inputs!F33) -> 1000000 | G12: =IF(G$7="",0,Inputs!G33) -> 1000000 | H12: =IF(H$7="",0,Inputs!H33) -> 1000000 | I12: =IF(I$7="",0,Inputs!I33) -> 0 | J12: =IF(J$7="",0,Inputs!J33) -> 0 | K12: =IF(K$7="",0,Inputs!K33) -> 0 | L12: =IF(L$7="",0,Inputs!L33) -> 0 | M12: =IF(M$7="",0,Inputs!M33) -> 0 | ... O12: =IF(O$7="",0,Inputs!O33) -> 0 | P12: =SUM(F12:O12) -> 3000000 | Q12: =P12+E12 -> 3000000 | R12: =Q12/Q$26 -> 0.09603073 | S12: =(F12*$F$51+G12*$G$51+H12*$H$51+I12*$I$51+J12*$J$51+K12*$K$51+L12*$L$51+M12*$M$51+N12*$N$51+O12*$O$51+E12)/($F$53+$E$26) -> 0.054274084 | T12: =$F$7*F12+$G$7*G12+$H$7*H12+$I$7*I12+$J$7*J12+$K$7*K12+$L$7*L12+$M$7*M12+$N$7*N12+$O$7*O12 -> 5500000
B13: =IF(Inputs!E34=0,Inputs!D34,CONCATENATE(Inputs!D34," (",Inputs!E34,")")) -> Inv D | C13: =IF(C$7="",0,Inputs!P34) -> 0 | D13: =IF(D$7="",0,Inputs!Q34) -> 0 | E13: =SUM(C13:D13) -> 0 | F13: =IF(F$7="",0,Inputs!F34) -> 1000000 | G13: =IF(G$7="",0,Inputs!G34) -> 1000000 | H13: =IF(H$7="",0,Inputs!H34) -> 1000000 | I13: =IF(I$7="",0,Inputs!I34) -> 0 | J13: =IF(J$7="",0,Inputs!J34) -> 0 | K13: =IF(K$7="",0,Inputs!K34) -> 0 | L13: =IF(L$7="",0,Inputs!L34) -> 0 | M13: =IF(M$7="",0,Inputs!M34) -> 0 | ... O13: =IF(O$7="",0,Inputs!O34) -> 0 | P13: =SUM(F13:O13) -> 3000000 | Q13: =P13+E13 -> 3000000 | R13: =Q13/Q$26 -> 0.09603073 | S13: =(F13*$F$51+G13*$G$51+H13*$H$51+I13*$I$51+J13*$J$51+K13*$K$51+L13*$L$51+M13*$M$51+N13*$N$51+O13*$O$51+E13)/($F$53+$E$26) -> 0.054274084 | T13: =$F$7*F13+$G$7*G13+$H$7*H13+$I$7*I13+$J$7*J13+$K$7*K13+$L$7*L13+$M$7*M13+$N$7*N13+$O$7*O13 -> 5500000
B14: =IF(Inputs!E35=0,Inputs!D35,CONCATENATE(Inputs!D35," (",Inputs!E35,")")) -> Inv E | C14: =IF(C$7="",0,Inputs!P35) -> 0 | D14: =IF(D$7="",0,Inputs!Q35) -> 0 | E14: =SUM(C14:D14) -> 0 | F14: =IF(F$7="",0,Inputs!F35) -> 1000000 | G14: =IF(G$7="",0,Inputs!G35) -> 1000000 | H14: =IF(H$7="",0,Inputs!H35) -> 1000000 | I14: =IF(I$7="",0,Inputs!I35) -> 0 | J14: =IF(J$7="",0,Inputs!J35) -> 0 | K14: =IF(K$7="",0,Inputs!K35) -> 0 | L14: =IF(L$7="",0,Inputs!L35) -> 0 | M14: =IF(M$7="",0,Inputs!M35) -> 0 | ... O14: =IF(O$7="",0,Inputs!O35) -> 0 | P14: =SUM(F14:O14) -> 3000000 | Q14: =P14+E14 -> 3000000 | R14: =Q14/Q$26 -> 0.09603073 | S14: =(F14*$F$51+G14*$G$51+H14*$H$51+I14*$I$51+J14*$J$51+K14*$K$51+L14*$L$51+M14*$M$51+N14*$N$51+O14*$O$51+E14)/($F$53+$E$26) -> 0.054274084 | T14: =$F$7*F14+$G$7*G14+$H$7*H14+$I$7*I14+$J$7*J14+$K$7*K14+$L$7*L14+$M$7*M14+$N$7*N14+$O$7*O14 -> 5500000
B15: =IF(Inputs!E36=0,Inputs!D36,CONCATENATE(Inputs!D36," (",Inputs!E36,")")) -> Inv F | C15: =IF(C$7="",0,Inputs!P36) -> 0 | D15: =IF(D$7="",0,Inputs!Q36) -> 0 | E15: =SUM(C15:D15) -> 0 | F15: =IF(F$7="",0,Inputs!F36) -> 0 | G15: =IF(G$7="",0,Inputs!G36) -> 0 | H15: =IF(H$7="",0,Inputs!H36) -> 1000000 | I15: =IF(I$7="",0,Inputs!I36) -> 3333333.3 | J15: =IF(J$7="",0,Inputs!J36) -> 0 | K15: =IF(K$7="",0,Inputs!K36) -> 0 | L15: =IF(L$7="",0,Inputs!L36) -> 0 | M15: =IF(M$7="",0,Inputs!M36) -> 0 | ... O15: =IF(O$7="",0,Inputs!O36) -> 0 | P15: =SUM(F15:O15) -> 4333333.3 | Q15: =P15+E15 -> 4333333.3 | R15: =Q15/Q$26 -> 0.13871105 | S15: =(F15*$F$51+G15*$G$51+H15*$H$51+I15*$I$51+J15*$J$51+K15*$K$51+L15*$L$51+M15*$M$51+N15*$N$51+O15*$O$51+E15)/($F$53+$E$26) -> 0.078395899 | T15: =$F$7*F15+$G$7*G15+$H$7*H15+$I$7*I15+$J$7*J15+$K$7*K15+$L$7*L15+$M$7*M15+$N$7*N15+$O$7*O15 -> 9166666.7
B16: =IF(Inputs!E37=0,Inputs!D37,CONCATENATE(Inputs!D37," (",Inputs!E37,")")) -> Inv G | C16: =IF(C$7="",0,Inputs!P37) -> 0 | D16: =IF(D$7="",0,Inputs!Q37) -> 0 | E16: =SUM(C16:D16) -> 0 | F16: =IF(F$7="",0,Inputs!F37) -> 0 | G16: =IF(G$7="",0,Inputs!G37) -> 0 | H16: =IF(H$7="",0,Inputs!H37) -> 1000000 | I16: =IF(I$7="",0,Inputs!I37) -> 3333333.3 | J16: =IF(J$7="",0,Inputs!J37) -> 0 | K16: =IF(K$7="",0,Inputs!K37) -> 0 | L16: =IF(L$7="",0,Inputs!L37) -> 0 | M16: =IF(M$7="",0,Inputs!M37) -> 0 | ... O16: =IF(O$7="",0,Inputs!O37) -> 0 | P16: =SUM(F16:O16) -> 4333333.3 | Q16: =P16+E16 -> 4333333.3 | R16: =Q16/Q$26 -> 0.13871105 | S16: =(F16*$F$51+G16*$G$51+H16*$H$51+I16*$I$51+J16*$J$51+K16*$K$51+L16*$L$51+M16*$M$51+N16*$N$51+O16*$O$51+E16)/($F$53+$E$26) -> 0.078395899 | T16: =$F$7*F16+$G$7*G16+$H$7*H16+$I$7*I16+$J$7*J16+$K$7*K16+$L$7*L16+$M$7*M16+$N$7*N16+$O$7*O16 -> 9166666.7
B17: =IF(Inputs!E38=0,Inputs!D38,CONCATENATE(Inputs!D38," (",Inputs!E38,")")) -> Inv H | C17: =IF(C$7="",0,Inputs!P38) -> 0 | D17: =IF(D$7="",0,Inputs!Q38) -> 0 | E17: =SUM(C17:D17) -> 0 | F17: =IF(F$7="",0,Inputs!F38) -> 0 | G17: =IF(G$7="",0,Inputs!G38) -> 0 | H17: =IF(H$7="",0,Inputs!H38) -> 1000000 | I17: =IF(I$7="",0,Inputs!I38) -> 3333333.3 | J17: =IF(J$7="",0,Inputs!J38) -> 0 | K17: =IF(K$7="",0,Inputs!K38) -> 0 | L17: =IF(L$7="",0,Inputs!L38) -> 0 | M17: =IF(M$7="",0,Inputs!M38) -> 0 | ... O17: =IF(O$7="",0,Inputs!O38) -> 0 | P17: =SUM(F17:O17) -> 4333333.3 | Q17: =P17+E17 -> 4333333.3 | R17: =Q17/Q$26 -> 0.13871105 | S17: =(F17*$F$51+G17*$G$51+H17*$H$51+I17*$I$51+J17*$J$51+K17*$K$51+L17*$L$51+M17*$M$51+N17*$N$51+O17*$O$51+E17)/($F$53+$E$26) -> 0.078395899 | T17: =$F$7*F17+$G$7*G17+$H$7*H17+$I$7*I17+$J$7*J17+$K$7*K17+$L$7*L17+$M$7*M17+$N$7*N17+$O$7*O17 -> 9166666.7
B18: =Inputs!D39 -> Other Investors | C18: =IF(C$7="",0,Inputs!P39) -> 0 | D18: =IF(D$7="",0,Inputs!Q39) -> 0 | E18: =SUM(C18:D18) -> 0 | F18: =IF(F$7="",0,Inputs!F39) -> 0 | G18: =IF(G$7="",0,Inputs!G39) -> 0 | H18: =IF(H$7="",0,Inputs!H39) -> 0 | I18: =IF(I$7="",0,Inputs!I39) -> 0 | J18: =IF(J$7="",0,Inputs!J39) -> 0 | K18: =IF(K$7="",0,Inputs!K39) -> 0 | L18: =IF(L$7="",0,Inputs!L39) -> 0 | M18: =IF(M$7="",0,Inputs!M39) -> 0 | ... O18: =IF(O$7="",0,Inputs!O39) -> 0 | P18: =SUM(F18:O18) -> 0 | Q18: =P18+E18 -> 0 | R18: =Q18/Q$26 -> 0 | S18: =(F18*$F$51+G18*$G$51+H18*$H$51+I18*$I$51+J18*$J$51+K18*$K$51+L18*$L$51+M18*$M$51+N18*$N$51+O18*$O$51+E18)/($F$53+$E$26) -> 0 | T18: =$F$7*F18+$G$7*G18+$H$7*H18+$I$7*I18+$J$7*J18+$K$7*K18+$L$7*L18+$M$7*M18+$N$7*N18+$O$7*O18 -> 0
B19: Warrants By Series | C19: =Inputs!N22 -> 0 | D19: =Inputs!N23 -> 0 | E19: =SUM(C19:D19) -> 0 | F19: {=IF(TRANSPOSE(Inputs!N$10:N$19)=0,0,TRANSPOSE(Inputs!N$10:N$19))} -> 10000 | G19: 10000 | H19: 10000 | I19: 10000 | J19: 0 | K19: 0 | L19: 0 | M19: 0 | N19: 0 | O19: 0 | P19: =SUM(F19:O19) -> 40000 | Q19: =P19+E19 -> 40000 | R19: =Q19/Q$26 -> 0.0012804097 | S19: =(F19*$F$51+G19*$G$51+H19*$H$51+I19*$I$51+J19*$J$51+K19*$K$51+L19*$L$51+M19*$M$51+N19*$N$51+O19*$O$51+E19)/($F$53+$E$26) -> 0.00072365445 | T19: =T38 -> 40000
B20: Subtotal Investors | C20: =SUM(C10:C18) -> 0 | D20: =SUM(D10:D18) -> 0 | E20: =SUM(E10:E18) -> 0 | F20: =SUM(F10:F19) -> 5010000 | G20: =SUM(G10:G19) -> 5010000 | H20: =SUM(H10:H19) -> 6010000 | I20: =SUM(I10:I19) -> 10010000 | J20: =SUM(J10:J19) -> 0 | K20: =SUM(K10:K19) -> 0 | L20: =SUM(L10:L19) -> 0 | M20: =SUM(M10:M19) -> 0 | ... T20: =SUM(T10:T19) -> 50040000
B22: =Inputs!D40 -> Management | C22: =IF(C$7=0,0,Inputs!P40) -> 5200000 | D22: =IF(D$7=0,0,Inputs!Q40) -> 0 | E22: =SUM(C22:D22) -> 5200000 | F22: =IF(F$7=0,0,Inputs!F40) -> 0 | G22: =IF(G$7=0,0,Inputs!G40) -> 0 | H22: =IF(H$7=0,0,Inputs!H40) -> 0 | I22: =IF(I$7=0,0,Inputs!I40) -> 0 | J22: =IF(J$7=0,0,Inputs!J40) -> 0 | K22: =IF(K$7=0,0,Inputs!K40) -> 0 | L22: =IF(L$7=0,0,Inputs!L40) -> 0 | M22: =IF(M$7=0,0,Inputs!M40) -> 0 | ... O22: =IF(O$7=0,0,Inputs!O40) -> 0 | P22: =SUM(F22:O22) -> 0 | Q22: =P22+E22 -> 5200000 | R22: =Q22/Q$26 -> 0.16645327 | S22: =(F22*$F$51+G22*$G$51+H22*$H$51+I22*$I$51+J22*$J$51+K22*$K$51+L22*$L$51+M22*$M$51+N22*$N$51+O22*$O$51+E22)/($F$53+$E$26) -> 0.094075079 | T22: =$F$7*F22+$G$7*G22+$H$7*H22+$I$7*I22+$J$7*J22+$K$7*K22+$L$7*L22+$M$7*M22+$N$7*N22+$O$7*O22 -> 0
B24: Subtotal Managers | C24: =SUM(C22:C23) -> 5200000 | D24: =SUM(D22:D23) -> 0 | E24: =SUM(E22:E23) -> 5200000 | F24: =SUM(F22:F23) -> 0 | G24: =SUM(G22:G23) -> 0 | H24: =SUM(H22:H23) -> 0 | I24: =SUM(I22:I23) -> 0 | J24: =SUM(J22:J23) -> 0 | ... T24: =SUM(T22:T23) -> 0
B26: Total Shares | C26: =C20+C24 -> 5200000 | D26: =D20+D24 -> 0 | E26: =E20+E24 -> 5200000 | F26: =F20+F24 -> 5010000 | G26: =G20+G24 -> 5010000 | H26: =H20+H24 -> 6010000 | I26: =I20+I24 -> 10010000 | J26: =J20+J24 -> 0 | ... S26: =S20+S24 -> 0.56517413
C28: <--------------------------------------------------------------------------------------------------------------- Amount Invested --------------------------------------------------------------------------------------------------------------->
B29: =IF(Inputs!E31=0,Inputs!D31,CONCATENATE(Inputs!D31," (",Inputs!E31,")")) -> HTGC | C29: =IF(C$7="","",Inputs!P31*C$7) -> 0 | D29: =IF(D$7="","",Inputs!Q31*D$7) -> 0 | E29: =SUM(C29:D29) -> 0 | F29: =IF(F$7="","",Inputs!F31*F$7) -> 1000000 | G29: =IF(G$7="","",Inputs!G31*G$7) -> 2000000 | H29: =IF(H$7="","",Inputs!H31*H$7) -> 0 | I29: =IF(I$7="","",Inputs!I31*I$7) -> 0 | J29: =IF(J$7="","",Inputs!J31*J$7) -> 0 | K29: =IF(K$7="","",Inputs!K31*K$7) -> 0 | L29: =IF(L$7="","",Inputs!L31*L$7) -> 0 | M29: =IF(M$7="","",Inputs!M31*M$7) -> 0 | ... O29: =IF(O$7="","",Inputs!O31*O$7) -> 0 | P29: =SUM(F29:O29) -> 3000000 | Q29: ='Pro Forma Cap Table'!Q10 -> 2000000 | R29: =Q29/$Q$26 -> 0.064020487 | S29: ='Pro Forma Cap Table'!S10 -> 0.064020487 | T29: =SUM(F29:O29) -> 3000000
B30: =IF(Inputs!E32=0,Inputs!D32,CONCATENATE(Inputs!D32," (",Inputs!E32,")")) -> Inv B | C30: =IF(C$7="","",Inputs!P32*C$7) -> 0 | D30: =IF(D$7="","",Inputs!Q32*D$7) -> 0 | E30: =SUM(C30:D30) -> 0 | F30: =IF(F$7="","",Inputs!F32*F$7) -> 1000000 | G30: =IF(G$7="","",Inputs!G32*G$7) -> 2000000 | H30: =IF(H$7="","",Inputs!H32*H$7) -> 0 | I30: =IF(I$7="","",Inputs!I32*I$7) -> 0 | J30: =IF(J$7="","",Inputs!J32*J$7) -> 0 | K30: =IF(K$7="","",Inputs!K32*K$7) -> 0 | L30: =IF(L$7="","",Inputs!L32*L$7) -> 0 | M30: =IF(M$7="","",Inputs!M32*M$7) -> 0 | ... O30: =IF(O$7="","",Inputs!O32*O$7) -> 0 | P30: =SUM(F30:O30) -> 3000000 | Q30: ='Pro Forma Cap Table'!Q11 -> 2000000 | R30: =Q30/$Q$26 -> 0.064020487 | S30: ='Pro Forma Cap Table'!S11 -> 0.064020487 | T30: =SUM(F30:O30) -> 3000000
B31: =IF(Inputs!E33=0,Inputs!D33,CONCATENATE(Inputs!D33," (",Inputs!E33,")")) -> Inv C | C31: =IF(C$7="","",Inputs!P33*C$7) -> 0 | D31: =IF(D$7="","",Inputs!Q33*D$7) -> 0 | E31: =SUM(C31:D31) -> 0 | F31: =IF(F$7="","",Inputs!F33*F$7) -> 1000000 | G31: =IF(G$7="","",Inputs!G33*G$7) -> 2000000 | H31: =IF(H$7="","",Inputs!H33*H$7) -> 2500000 | I31: =IF(I$7="","",Inputs!I33*I$7) -> 0 | J31: =IF(J$7="","",Inputs!J33*J$7) -> 0 | K31: =IF(K$7="","",Inputs!K33*K$7) -> 0 | L31: =IF(L$7="","",Inputs!L33*L$7) -> 0 | M31: =IF(M$7="","",Inputs!M33*M$7) -> 0 | ... O31: =IF(O$7="","",Inputs!O33*O$7) -> 0 | P31: =SUM(F31:O31) -> 5500000 | Q31: ='Pro Forma Cap Table'!Q12 -> 3000000 | R31: =Q31/$Q$26 -> 0.09603073 | S31: ='Pro Forma Cap Table'!S12 -> 0.09603073 | T31: =SUM(F31:O31) -> 5500000
B32: =IF(Inputs!E34=0,Inputs!D34,CONCATENATE(Inputs!D34," (",Inputs!E34,")")) -> Inv D | C32: =IF(C$7="","",Inputs!P34*C$7) -> 0 | D32: =IF(D$7="","",Inputs!Q34*D$7) -> 0 | E32: =SUM(C32:D32) -> 0 | F32: =IF(F$7="","",Inputs!F34*F$7) -> 1000000 | G32: =IF(G$7="","",Inputs!G34*G$7) -> 2000000 | H32: =IF(H$7="","",Inputs!H34*H$7) -> 2500000 | I32: =IF(I$7="","",Inputs!I34*I$7) -> 0 | J32: =IF(J$7="","",Inputs!J34*J$7) -> 0 | K32: =IF(K$7="","",Inputs!K34*K$7) -> 0 | L32: =IF(L$7="","",Inputs!L34*L$7) -> 0 | M32: =IF(M$7="","",Inputs!M34*M$7) -> 0 | ... O32: =IF(O$7="","",Inputs!O34*O$7) -> 0 | P32: =SUM(F32:O32) -> 5500000 | Q32: ='Pro Forma Cap Table'!Q13 -> 3000000 | R32: =Q32/$Q$26 -> 0.09603073 | S32: ='Pro Forma Cap Table'!S13 -> 0.09603073 | T32: =SUM(F32:O32) -> 5500000
B33: =IF(Inputs!E35=0,Inputs!D35,CONCATENATE(Inputs!D35," (",Inputs!E35,")")) -> Inv E | C33: =IF(C$7="","",Inputs!P35*C$7) -> 0 | D33: =IF(D$7="","",Inputs!Q35*D$7) -> 0 | E33: =SUM(C33:D33) -> 0 | F33: =IF(F$7="","",Inputs!F35*F$7) -> 1000000 | G33: =IF(G$7="","",Inputs!G35*G$7) -> 2000000 | H33: =IF(H$7="","",Inputs!H35*H$7) -> 2500000 | I33: =IF(I$7="","",Inputs!I35*I$7) -> 0 | J33: =IF(J$7="","",Inputs!J35*J$7) -> 0 | K33: =IF(K$7="","",Inputs!K35*K$7) -> 0 | L33: =IF(L$7="","",Inputs!L35*L$7) -> 0 | M33: =IF(M$7="","",Inputs!M35*M$7) -> 0 | ... O33: =IF(O$7="","",Inputs!O35*O$7) -> 0 | P33: =SUM(F33:O33) -> 5500000 | Q33: ='Pro Forma Cap Table'!Q14 -> 3000000 | R33: =Q33/$Q$26 -> 0.09603073 | S33: ='Pro Forma Cap Table'!S14 -> 0.09603073 | T33: =SUM(F33:O33) -> 5500000
B34: =IF(Inputs!E36=0,Inputs!D36,CONCATENATE(Inputs!D36," (",Inputs!E36,")")) -> Inv F | C34: =IF(C$7="","",Inputs!P36*C$7) -> 0 | D34: =IF(D$7="","",Inputs!Q36*D$7) -> 0 | E34: =SUM(C34:D34) -> 0 | F34: =IF(F$7="","",Inputs!F36*F$7) -> 0 | G34: =IF(G$7="","",Inputs!G36*G$7) -> 0 | H34: =IF(H$7="","",Inputs!H36*H$7) -> 2500000 | I34: =IF(I$7="","",Inputs!I36*I$7) -> 6666666.7 | J34: =IF(J$7="","",Inputs!J36*J$7) -> 0 | K34: =IF(K$7="","",Inputs!K36*K$7) -> 0 | L34: =IF(L$7="","",Inputs!L36*L$7) -> 0 | M34: =IF(M$7="","",Inputs!M36*M$7) -> 0 | ... O34: =IF(O$7="","",Inputs!O36*O$7) -> 0 | P34: =SUM(F34:O34) -> 9166666.7 | Q34: ='Pro Forma Cap Table'!Q15 -> 4333333.3 | R34: =Q34/$Q$26 -> 0.13871105 | S34: ='Pro Forma Cap Table'!S15 -> 0.13871105 | T34: =SUM(F34:O34) -> 9166666.7
B35: =IF(Inputs!E37=0,Inputs!D37,CONCATENATE(Inputs!D37," (",Inputs!E37,")")) -> Inv G | C35: =IF(C$7="","",Inputs!P37*C$7) -> 0 | D35: =IF(D$7="","",Inputs!Q37*D$7) -> 0 | E35: =SUM(C35:D35) -> 0 | F35: =IF(F$7="","",Inputs!F37*F$7) -> 0 | G35: =IF(G$7="","",Inputs!G37*G$7) -> 0 | H35: =IF(H$7="","",Inputs!H37*H$7) -> 2500000 | I35: =IF(I$7="","",Inputs!I37*I$7) -> 6666666.7 | J35: =IF(J$7="","",Inputs!J37*J$7) -> 0 | K35: =IF(K$7="","",Inputs!K37*K$7) -> 0 | L35: =IF(L$7="","",Inputs!L37*L$7) -> 0 | M35: =IF(M$7="","",Inputs!M37*M$7) -> 0 | ... O35: =IF(O$7="","",Inputs!O37*O$7) -> 0 | P35: =SUM(F35:O35) -> 9166666.7 | Q35: ='Pro Forma Cap Table'!Q16 -> 4333333.3 | R35: =Q35/$Q$26 -> 0.13871105 | S35: ='Pro Forma Cap Table'!S16 -> 0.13871105 | T35: =SUM(F35:O35) -> 9166666.7
B36: =IF(Inputs!E38=0,Inputs!D38,CONCATENATE(Inputs!D38," (",Inputs!E38,")")) -> Inv H | C36: =IF(C$7="","",Inputs!P38*C$7) -> 0 | D36: =IF(D$7="","",Inputs!Q38*D$7) -> 0 | E36: =SUM(C36:D36) -> 0 | F36: =IF(F$7="","",Inputs!F38*F$7) -> 0 | G36: =IF(G$7="","",Inputs!G38*G$7) -> 0 | H36: =IF(H$7="","",Inputs!H38*H$7) -> 2500000 | I36: =IF(I$7="","",Inputs!I38*I$7) -> 6666666.7 | J36: =IF(J$7="","",Inputs!J38*J$7) -> 0 | K36: =IF(K$7="","",Inputs!K38*K$7) -> 0 | L36: =IF(L$7="","",Inputs!L38*L$7) -> 0 | M36: =IF(M$7="","",Inputs!M38*M$7) -> 0 | ... O36: =IF(O$7="","",Inputs!O38*O$7) -> 0 | P36: =SUM(F36:O36) -> 9166666.7 | Q36: ='Pro Forma Cap Table'!Q17 -> 4333333.3 | R36: =Q36/$Q$26 -> 0.13871105 | S36: ='Pro Forma Cap Table'!S17 -> 0.13871105 | T36: =SUM(F36:O36) -> 9166666.7
B37: =Inputs!D39 -> Other Investors | C37: =IF(C$7="","",Inputs!P39*C$7) -> 0 | D37: =IF(D$7="","",Inputs!Q39*D$7) -> 0 | E37: =SUM(C37:D37) -> 0 | F37: =IF(F$7="","",Inputs!F39*F$7) -> 0 | G37: =IF(G$7="","",Inputs!G39*G$7) -> 0 | H37: =IF(H$7="","",Inputs!H39*H$7) -> 0 | I37: =IF(I$7="","",Inputs!I39*I$7) -> 0 | J37: =IF(J$7="","",Inputs!J39*J$7) -> 0 | K37: =IF(K$7="","",Inputs!K39*K$7) -> 0 | L37: =IF(L$7="","",Inputs!L39*L$7) -> 0 | M37: =IF(M$7="","",Inputs!M39*M$7) -> 0 | ... O37: =IF(O$7="","",Inputs!O39*O$7) -> 0 | P37: =SUM(F37:O37) -> 0 | Q37: ='Pro Forma Cap Table'!Q18 -> 0 | R37: =Q37/$Q$26 -> 0 | S37: ='Pro Forma Cap Table'!S18 -> 0 | T37: =SUM(F37:O37) -> 0
B38: Warrants By Series | C38: =C19*Inputs!$K$20 -> 0 | D38: =D19*Inputs!$K$20 -> 0 | F38: =F19*Inputs!O10 -> 10000 | G38: =G19*Inputs!$O11 -> 10000 | H38: =H19*Inputs!$O12 -> 10000 | I38: =I19*Inputs!$O13 -> 10000 | J38: =J19*Inputs!$O14 -> 0 | K38: =K19*Inputs!$O15 -> 0 | L38: =L19*Inputs!$O16 -> 0 | M38: =M19*Inputs!$O17 -> 0 | N38: =N19*Inputs!$O18 -> 0 | O38: =O19*Inputs!$O19 -> 0 | P38: =SUM(F38:O38) -> 40000 | Q38: ='Pro Forma Cap Table'!Q19 -> 40000 | R38: =Q38/$Q$26 -> 0.0012804097 | S38: ='Pro Forma Cap Table'!S19 -> 0.0012804097 | T38: =SUM(F38:O38) -> 40000
B39: Subtotal Investors | C39: =SUM(C29:C37) -> 0 | D39: =SUM(D29:D37) -> 0 | E39: =SUM(E29:E37) -> 0 | F39: =SUM(F29:F38) -> 5010000 | G39: =SUM(G29:G38) -> 10010000 | H39: =SUM(H29:H38) -> 15010000 | I39: =SUM(I29:I38) -> 20010000 | J39: =SUM(J29:J38) -> 0 | K39: =SUM(K29:K38) -> 0 | L39: =SUM(L29:L38) -> 0 | M39: =SUM(M29:M38) -> 0 | ... T39: =SUM(T29:T38) -> 50040000
B41: =Inputs!D40 -> Management | C41: =IF(C$7=0,0,Inputs!M22*C7) -> 0.052 | D41: =IF(D$7=0,0,Inputs!M23*D7) -> 0 | E41: =SUM(C41:D41) -> 0.052 | F41: =IF(F$7=0,0,Inputs!F40*F$7) -> 0 | G41: =IF(G$7=0,0,Inputs!G40*G$7) -> 0 | H41: =IF(H$7=0,0,Inputs!H40*H$7) -> 0 | I41: =IF(I$7=0,0,Inputs!I40*I$7) -> 0 | J41: =IF(J$7=0,0,Inputs!J40*J$7) -> 0 | K41: =IF(K$7=0,0,Inputs!K40*K$7) -> 0 | L41: =IF(L$7=0,0,Inputs!L40*L$7) -> 0 | M41: =IF(M$7=0,0,Inputs!M40*M$7) -> 0 | ... O41: =IF(O$7=0,0,Inputs!O40*O$7) -> 0 | P41: =SUM(F41:O41) -> 0 | Q41: =Q22 -> 5200000 | R41: =Q41/Q$26 -> 0.16645327 | S41: ='Pro Forma Cap Table'!S22 -> 0.16645327 | T41: =T22 -> 0
B43: Subtotal Managers | C43: =SUM(C41:C42) -> 0.052 | D43: =SUM(D41:D42) -> 0 | E43: =SUM(E41:E42) -> 0.052 | F43: =SUM(F41:F42) -> 0 | G43: =SUM(G41:G42) -> 0 | H43: =SUM(H41:H42) -> 0 | I43: =SUM(I41:I42) -> 0 | J43: =SUM(J41:J42) -> 0 | ... T43: =SUM(T41:T42) -> 0
B45: Total Dollars | C45: =C2120*C7 -> 0.052 | D45: =D2120*D7 -> 0 | E45: =SUM(C45:D45) -> 0.052 | F45: =IF(F7=0,"N/A",F$2120*F$7) -> 5010000 | G45: =IF(G7=0,"N/A",G$2120*G$7) -> 10020000 | H45: =IF(H7=0,"N/A",H$2120*H$7) -> 15025000 | I45: =IF(I7=0,"N/A",I$2120*I$7) -> 20020000 | J45: =IF(J7=0,"N/A",J$2120*J$7) -> N/A | K45: =IF(K7=0,"N/A",K$2120*K$7) -> N/A | L45: =IF(L7=0,"N/A",L$2120*L$7) -> N/A | M45: =IF(M7=0,"N/A",M$2120*M$7) -> N/A | ... O45: =IF(O7=0,"N/A",O$2120*O$7) -> N/A | P45: =SUM(F45:O45) -> 50075000 | R45: =R39+R43 -> 1 | S45: =S39+S43 -> 1 | T45: =T39+T43 -> 50040000
D46: Post-Money | F46: {=IF(TRANSPOSE(Inputs!F$10:F$19)=0,"N/A",TRANSPOSE(Inputs!F$10:F$19))} -> N/A | G46: N/A | H46: N/A | I46: N/A | J46: N/A | K46: N/A | L46: N/A | M46: N/A | N46: N/A | O46: N/A | Q46: Total Liquidation Preference | T46: =F2121*F47+G2121*G47+H2121*H47+I2121*I47+J2121*J47+K2121*K47+L2121*L47+M2121*M47+N2121*N47+O2121*O47 -> 50075000
D47: Liq. Pref. Multiple | F47: {=IF(TRANSPOSE(Inputs!G$10:G$19)=0,0,TRANSPOSE(Inputs!G$10:G$19))} -> 1 | G47: 1 | H47: 1 | I47: 1 | J47: 1 | K47: 1 | L47: 1 | M47: 1 | N47: 1 | O47: 1 | Q47: =IF(G7=0,F6,IF(H7=0,G6,IF(I7=0,H6,IF(J7=0,I6,IF(K7=0,J6,IF(L7=0,K6,IF(M7=0,L6,IF(N7=0,M6,IF(O7=0,N6,O6))))))))) -> Series D | R47: ful. dil. post-money valuation of | T47: =R48*Q26 -> 62480000
D48: Cap | F48: {=IF(TRANSPOSE(Inputs!H$10:H$19)=0,0,TRANSPOSE(Inputs!H$10:H$19))} -> 2 | G48: 2 | H48: 2 | I48: 2 | J48: 2 | K48: 2 | L48: 2 | M48: 2 | N48: 2 | O48: 2 | Q48: Based on | R48: =IF(G7=0,F7,IF(H7=0,G7,IF(I7=0,H7,IF(J7=0,I7,IF(K7=0,J7,IF(L7=0,K7,IF(M7=0,L7,IF(N7=0,M7,IF(O7=0,N7,O7))))))))) -> 2 | S48: per share price.
...

Sheet Summary
B1: =Inputs!I6 -> Company Name
B2: Pro Forma Capitalization Table
B3: =Inputs!I7 -> 39813
F5: {=IF(TRANSPOSE(Inputs!E$10:E$19)=0,"",TRANSPOSE(Inputs!E$10:E$19))} -> 39113 | G5: 39478 | H5: 39843 | I5: 39843 | J5: 39843 | K5: 39843 | L5: 39843 | M5: 39843 | N5: 39843 | O5: 39843
C6: Common | D6: Stock | E6: Total | F6: {=IF(TRANSPOSE(Inputs!D$10:D$19)=0,"",TRANSPOSE(Inputs!D$10:D$19))} -> Series A | G6: Series B | H6: Series C | I6: Series D | J6: - | K6: - | L6: - | M6: - | N6: - | O6: - | P6: Total | Q6: Total # | R6: Ful. Dil. as Conv. | W6: Total | X6: Total # | Y6: Total
B7: Investor (Partner) | C7: =Inputs!K22 -> 1e-08 | D7: =Inputs!K23 -> 1e-07 | E7: Common | F7: {=IF(TRANSPOSE(Inputs!K$10:K$19)=0,0,TRANSPOSE(Inputs!K$10:K$19))} -> 1 | G7: 2 | H7: 2.5 | I7: 2 | J7: 0 | K7: 0 | L7: 0 | M7: 0 | N7: 0 | O7: 0 | P7: Dollars ($) | Q7: Of All | R7: Ownership | W7: Preferred | X7: Of All | Y7: Ownership
C8: Shares | D8: Options | E8: & Options | F8: =IF(F7=0,"","Preferred") -> Preferred | G8: =IF(G7=0,"","Preferred") -> Preferred | H8: =IF(H7=0,"","Preferred") -> Preferred | I8: =IF(I7=0,"","Preferred") -> Preferred | J8: =IF(J7=0,"","Preferred") | K8: =IF(K7=0,"","Preferred") | L8: =IF(L7=0,"","Preferred") | M8: =IF(M7=0,"","Preferred") | ... O8: =IF(O7=0,"","Preferred") | P8: Invested | Q8: Shares Held | R8: Percent (%) | W8: Shares | X8: Shares Held | Y8: Percent (%)
B9: =IF(Inputs!E31=0,Inputs!D31,CONCATENATE(Inputs!D31," (",Inputs!E31,")")) -> HTGC | C9: ='Pro Forma Cap Table'!C29 -> 0 | D9: ='Pro Forma Cap Table'!D29 -> 0 | E9: =SUM(C9:D9) -> 0 | F9: ='Pro Forma Cap Table'!F29 -> 1000000 | G9: ='Pro Forma Cap Table'!G29 -> 2000000 | H9: ='Pro Forma Cap Table'!H29 -> 0 | I9: ='Pro Forma Cap Table'!I29 -> 0 | J9: ='Pro Forma Cap Table'!J29 -> 0 | K9: ='Pro Forma Cap Table'!K29 -> 0 | L9: ='Pro Forma Cap Table'!L29 -> 0 | M9: ='Pro Forma Cap Table'!M29 -> 0 | ... O9: ='Pro Forma Cap Table'!O29 -> 0 | P9: ='Pro Forma Cap Table'!T10 -> 3000000 | Q9: ='Pro Forma Cap Table'!Q10 -> 2000000 | R9: ='Pro Forma Cap Table'!S10 -> 0.064020487 | W9: =SUM(AN9:AW9) -> 2000000 | X9: =W9+AM9 -> 2000000 | Y9: =X9/X$27 -> 0.064020487 | AJ9: =IF(Inputs!E31=0,Inputs!D31,CONCATENATE(Inputs!D31," (",Inputs!E31,")")) -> HTGC | AK9: 0 | AL9: 0 | AM9: =SUM(AK9:AL9) -> 0 | AN9: =IF(F$7="",0,Inputs!F31) -> 1000000 | AO9: =IF(G$7="",0,Inputs!G31) -> 1000000 | AP9: =IF(H$7="",0,Inputs!H31) -> 0 | AQ9: =IF(I$7="",0,Inputs!I31) -> 0 | AR9: =IF(J$7="",0,Inputs!J31) -> 0 | AS9: =IF(K$7="",0,Inputs!K31) -> 0 | AT9: =IF(L$7="",0,Inputs!L31) -> 0 | AU9: =IF(M$7="",0,Inputs!M31) -> 0 | ... AW9: =IF(O$7="",0,Inputs!O31) -> 0 | AX9: =$F$7*AN9+$G$7*AO9+$H$7*AP9+$I$7*AQ9+$J$7*AR9+$K$7*AS9+$L$7*AT9+$M$7*AU9+$N$7*AV9+$O$7*AW9 -> 3000000 | AY9: =(AN9*$AA$61+AO9*$AB$61+AP9*$AC$61+AQ9*$AD$61+AR9*$AE$61+AS9*$AF$61+AT9*$AG$61+AU9*$AH$61+AV9*$AI$61+AW9*$AJ$61+AM9)/($R$31+$X$21) -> 0.064020487
B10: =IF(Inputs!E32=0,Inputs!D32,CONCATENATE(Inputs!D32," (",Inputs!E32,")")) -> Inv B | C10: ='Pro Forma Cap Table'!C30 -> 0 | D10: ='Pro Forma Cap Table'!D30 -> 0 | E10: =SUM(C10:D10) -> 0 | F10: ='Pro Forma Cap Table'!F30 -> 1000000 | G10: ='Pro Forma Cap Table'!G30 -> 2000000 | H10: ='Pro Forma Cap Table'!H30 -> 0 | I10: ='Pro Forma Cap Table'!I30 -> 0 | J10: ='Pro Forma Cap Table'!J30 -> 0 | K10: ='Pro Forma Cap Table'!K30 -> 0 | L10: ='Pro Forma Cap Table'!L30 -> 0 | M10: ='Pro Forma Cap Table'!M30 -> 0 | ... O10: ='Pro Forma Cap Table'!O30 -> 0 | P10: ='Pro Forma Cap Table'!T11 -> 3000000 | Q10: ='Pro Forma Cap Table'!Q11 -> 2000000 | R10: ='Pro Forma Cap Table'!S11 -> 0.064020487 | W10: =SUM(AN10:AW10) -> 2000000 | X10: =W10+AM10 -> 2000000 | Y10: =X10/X$27 -> 0.064020487 | AJ10: =IF(Inputs!E32=0,Inputs!D32,CONCATENATE(Inputs!D32," (",Inputs!E32,")")) -> Inv B | AK10: 0 | AL10: 0 | AM10: =SUM(AK10:AL10) -> 0 | AN10: =IF(F$7="",0,Inputs!F32) -> 1000000 | AO10: =IF(G$7="",0,Inputs!G32) -> 1000000 | AP10: =IF(H$7="",0,Inputs!H32) -> 0 | AQ10: =IF(I$7="",0,Inputs!I32) -> 0 | AR10: =IF(J$7="",0,Inputs!J32) -> 0 | AS10: =IF(K$7="",0,Inputs!K32) -> 0 | AT10: =IF(L$7="",0,Inputs!L32) -> 0 | AU10: =IF(M$7="",0,Inputs!M32) -> 0 | ... AW10: =IF(O$7="",0,Inputs!O32) -> 0 | AX10: =$F$7*AN10+$G$7*AO10+$H$7*AP10+$I$7*AQ10+$J$7*AR10+$K$7*AS10+$L$7*AT10+$M$7*AU10+$N$7*AV10+$O$7*AW10 -> 3000000 | AY10: =(AN10*$AA$61+AO10*$AB$61+AP10*$AC$61+AQ10*$AD$61+AR10*$AE$61+AS10*$AF$61+AT10*$AG$61+AU10*$AH$61+AV10*$AI$61+AW10*$AJ$61+AM10)/($R$31+$X$21) -> 0.064020487
